Workbook

Sheet README
B2: MCBOMs Harwood (2003) Validation — $50M Budget
B4: Purpose
B5: This workbook implements the MCBOMs MILP — the same Mixed-Integer Linear Program specified in Chapter 2 of the Methodology document and implemented in Python in the project's optimizer module — using the Solver add-in built into Microsoft Excel. It validates the MILP against the Harwood et al. (2003) 10-site case study at the $50M budget level. Cost and benefit values are taken directly from Tables 2 and 3 of the published paper. Following Harwood's definition, net benefit is computed as (PSB + PTOB) − Safety Improvement Cost; resurfacing cost is in the budget constraint but not the objective, since resurfacing is treated as a baseline that occurs regardless of which alternative is selected. All five forms of the MCBOMs MILP — Python, AMPL, GAMS, LP, and this Excel implementation — produce numerically identical results (subject to the documented PNR caveat at constrained budgets). Project website: https://ttitamu.github.io/mcboms-optimization.
B11: Problem
B12: 10 candidate sites, 21 total alternatives. The optimizer chooses at most one alternative per site, subject to a $50,000,000 total budget.
B17: Expected result
B18: Quantity | C18: Value
B19: Total expenditure | C19: 16271247
B20: Total net benefit (objective) | C20: 6159512
B21: Budget | C21: 50000000
B22: Budget utilization | C22: 0.32542494
B25: How to run
B26: 1. Open this workbook in Microsoft Excel (desktop). The Solver add-in must be enabled — see 'How to enable the Solver add-in' below if Solver does not appear on the Data tab.
B27: 2. Go to the 'Optimization' sheet. Verify that the decision-variable cells (yellow-shaded, 'Fund? (0/1)' column) are currently 0.
B28: 3. On the Data tab, click Solver. The Solver Parameters dialog opens.
B29: 4. Configure Solver per the instructions on the right-side panel of the 'Optimization' sheet (objective cell, decision range, constraints).
B30: 5. Click Solve. When the Solver Results dialog appears, choose 'Keep Solver Solution' and click OK.
B31: 6. Verify the answer matches the 'Expected result' table above. The 'Results' sheet shows the selected alternatives and a match indicator that displays 'Run Solver' (yellow) before Solver has been used, 'PASS' (green) once the optimal answer is reached, or 'FAIL' (red) if the answer does not match.
B33: How to enable the Solver add-in (one-time setup)
B34: Skip this section if the Solver button is already visible on the Data tab.
B35: 1. File → Options → Add-ins.
B36: 2. At the bottom, set Manage to 'Excel Add-ins' and click Go.
B37: 3. Check the 'Solver Add-in' box and click OK.
... B43: MCBOMs project website — https://ttitamu.github.io/mcboms-optimization

Sheet Inputs
B2: Inputs (Harwood Tables 2 and 3)
B3: Cost and benefit values from Tables 2 and 3 of Harwood et al. (2003). Net benefit is computed as Total Benefit − Safety Improvement Cost (Harwood Eq. 3 definition: resurfacing is treated as a baseline cost that occurs regardless of which alternative is selected, so the net benefit measures the value of safety improvements above that baseline).
B8: Budget | E8: 50000000
B10: Site | C10: Alt | D10: Description | E10: Resurf cost | F10: Safety cost | G10: Total cost | H10: Safety ben | I10: Ops ben | J10: Total ben | K10: Net benefit
B11: 1 | C11: 0 | D11: Do nothing | E11: 0 | F11: 0 | G11: =E11+F11 | H11: 0 | I11: 0 | J11: =H11+I11 | K11: =J11-F11
B12: 1 | C12: 1 | D12: Resurface only | E12: 528803 | F12: 0 | G12: =E12+F12 | H12: 0 | I12: 35107 | J12: =H12+I12 | K12: =J12-F12
B13: 2 | C13: 0 | D13: Do nothing | E13: 0 | F13: 0 | G13: =E13+F13 | H13: 0 | I13: 0 | J13: =H13+I13 | K13: =J13-F13
B14: 2 | C14: 1 | D14: Resurface + Turn-lane improvements | E14: 519763 | F14: 120000 | G14: =E14+F14 | H14: 328176 | I14: 71580 | J14: =H14+I14 | K14: =J14-F14
B15: 3 | C15: 0 | D15: Do nothing | E15: 0 | F15: 0 | G15: =E15+F15 | H15: 0 | I15: 0 | J15: =H15+I15 | K15: =J15-F15
B16: 3 | C16: 1 | D16: Resurface + Turn-lane + Roadside + User-defined #2 | E16: 821621 | F16: 560000 | G16: =E16+F16 | H16: 1094909 | I16: 93697 | J16: =H16+I16 | K16: =J16-F16
B17: 4 | C17: 0 | D17: Do nothing | E17: 0 | F17: 0 | G17: =E17+F17 | H17: 0 | I17: 0 | J17: =H17+I17 | K17: =J17-F17
B18: 4 | C18: 1 | D18: Resurface + Widen lanes 10-11ft + Widen shoulders 4-6ft | E18: 475200 | F18: 572616 | G18: =E18+F18 | H18: 775629 | I18: 58379 | J18: =H18+I18 | K18: =J18-F18
B19: 5 | C19: 0 | D19: Do nothing | E19: 0 | F19: 0 | G19: =E19+F19 | H19: 0 | I19: 0 | J19: =H19+I19 | K19: =J19-F19
B20: 5 | C20: 1 | D20: Resurface + Turn-lane improvements | E20: 1180017 | F20: 240000 | G20: =E20+F20 | H20: 1355589 | I20: 53029 | J20: =H20+I20 | K20: =J20-F20
B21: 6 | C21: 0 | D21: Do nothing | E21: 0 | F21: 0 | G21: =E21+F21 | H21: 0 | I21: 0 | J21: =H21+I21 | K21: =J21-F21
B22: 6 | C22: 1 | D22: Resurface + Turn-lane improvements | E22: 2508549 | F22: 560000 | G22: =E22+F22 | H22: 808637 | I22: 92800 | J22: =H22+I22 | K22: =J22-F22
... B31: 10 | C31: 1 | D31: Resurface + Widen shoulders 4-6ft + Horiz curve + Turn-lane | E31: 1488369 | F31: 1052781 | G31: =E31+F31 | H31: 2329256 | I31: 80186 | J31: =H31+I31 | K31: =J31-F31

Sheet Derivation
B2: Derivation Reference (Site 5: Resurface + Turn-lane)
B4: Shows how the cost and benefit values on the Inputs sheet are derived from raw inputs using the methodology described in Section 2.3 of the MCBOMs Methodology. Site 5 (Resurface + Turn-lane improvements) is the representative example. The published Harwood paper does not report the raw crash data, so the values are forward-derivable from Tables 2 and 3 but not back-checkable; the derivation chain shown here documents what each Table 2/3 value represents in the methodology.
B11: Cost derivation
B12: Resurfacing cost (mileage × unit rate) | C12: from paper Table 2 | D12: $1,180,017
B13: Safety improvement cost (turn-lane installation) | C13: from paper Table 2 | D13: $240,000
B14: Total cost (CC_jk in Eq. 3) | C14: Resurf + Safety | D14: $1,420,017
B16: Benefit derivation
B17: E_no-build (annual expected crashes by severity) | C17: HSM SPF or local data | D17: (per-site)
B18: E_build = E_no-build × AMF (CMF in HSM terminology) | C18: AMFs from Harwood Table 1 | D18: (per-treatment)
B19: Annual reduction = E_no-build − E_build | C19: reduction by severity | D19: (per-treatment)
B20: Annual safety benefit = Σ (reduction × unit cost) | C20: FHWA crash unit costs | D20: (per-treatment)
B21: PSB = Annual safety benefit × PWF(r, T) | C21: PWF(0.07, 20) = 10.594 | D21: $1,355,589
B22: PTOB (operational benefit, travel time savings) | C22: Harwood Table 3 | D22: $53,029
B23: Total benefit = PSB + PTOB | C23: (safety + operational) | D23: $1,408,618
B24: Net benefit = Total benefit − Safety Improvement Cost | C24: Eq. 3 in paper | D24: $1,168,618
B26: Note on PNR / PRP terms
B27: Harwood's full equation includes Penalty for Not Resurfacing (PNR) and Penalty for Resurfacing without Improvements (PRP). These are set to zero in this validation because per-site PNR values are not published in the paper and the PNR mechanism requires pavement-deterioration data not standardized in current FHWA guidance. At the $50M budget, PNR has no effect on the optimal selection. At lower budgets (e.g. $10M), MCBOMs may select a different portfolio than Harwood's published solution; this is documented in MCBOMs Methodology Section 2.7.

Sheet Optimization
B2: Optimization (MILP)
B5: Mathematical Formulation | N5: Site | O5: Alt | P5: Description | Q5: Cost | R5: Total benefit | S5: Net benefit | T5: Fund? (0/1)
B6: Decision variables | N6: 1 | O6: 0 | P6: Do nothing | Q6: =Inputs!G11 | R6: =Inputs!J11 | S6: =Inputs!K11 | T6: 0
B7: x_ij ∈ {0, 1} for each alternative j at site i (range T6:T26, yellow cells) | N7: 1 | O7: 1 | P7: Resurface only | Q7: =Inputs!G12 | R7: =Inputs!J12 | S7: =Inputs!K12 | T7: 0
N8: 2 | O8: 0 | P8: Do nothing | Q8: =Inputs!G13 | R8: =Inputs!J13 | S8: =Inputs!K13 | T8: 0
B9: Objective | N9: 2 | O9: 1 | P9: Resurface + Turn-lane improvements | Q9: =Inputs!G14 | R9: =Inputs!J14 | S9: =Inputs!K14 | T9: 0
B10: Maximize: Z = Σ_i Σ_j NetBenefit_ij × x_ij | N10: 3 | O10: 0 | P10: Do nothing | Q10: =Inputs!G15 | R10: =Inputs!J15 | S10: =Inputs!K15 | T10: 0
B11: (computed at cell Q32) | N11: 3 | O11: 1 | P11: Resurface + Turn-lane + Roadside + User-defined #2 | Q11: =Inputs!G16 | R11: =Inputs!J16 | S11: =Inputs!K16 | T11: 0
N12: 4 | O12: 0 | P12: Do nothing | Q12: =Inputs!G17 | R12: =Inputs!J17 | S12: =Inputs!K17 | T12: 0
B13: Subject to | N13: 4 | O13: 1 | P13: Resurface + Widen lanes 10-11ft + Widen shoulders 4-6ft | Q13: =Inputs!G18 | R13: =Inputs!J18 | S13: =Inputs!K18 | T13: 0
B14: Budget: Σ_i Σ_j Cost_ij × x_ij ≤ Budget | N14: 5 | O14: 0 | P14: Do nothing | Q14: =Inputs!G19 | R14: =Inputs!J19 | S14: =Inputs!K19 | T14: 0
B15: (computed at Q30, ≤ $50,000,000) | N15: 5 | O15: 1 | P15: Resurface + Turn-lane improvements | Q15: =Inputs!G20 | R15: =Inputs!J20 | S15: =Inputs!K20 | T15: 0
B16: Mutex: Σ_j x_ij ≤ 1 for each site i | N16: 6 | O16: 0 | P16: Do nothing | Q16: =Inputs!G21 | R16: =Inputs!J21 | S16: =Inputs!K21 | T16: 0
B17: (constraint cells, O37:O46) | N17: 6 | O17: 1 | P17: Resurface + Turn-lane improvements | Q17: =Inputs!G22 | R17: =Inputs!J22 | S17: =Inputs!K22 | T17: 0
B18: Binary: x_ij ∈ {0, 1} | N18: 7 | O18: 0 | P18: Do nothing | Q18: =Inputs!G23 | R18: =Inputs!J23 | S18: =Inputs!K23 | T18: 0
N19: 7 | O19: 1 | P19: Resurface + Turn-lane improvements | Q19: =Inputs!G24 | R19: =Inputs!J24 | S19: =Inputs!K24 | T19: 0
B20: Solver Setup | N20: 8 | O20: 0 | P20: Do nothing | Q20: =Inputs!G25 | R20: =Inputs!J25 | S20: =Inputs!K25 | T20: 0
B21: Top of Solver dialog | N21: 8 | O21: 1 | P21: Resurface + Turn-lane improvements | Q21: =Inputs!G26 | R21: =Inputs!J26 | S21: =Inputs!K26 | T21: 0
B22: Field | C22: Value | N22: 8 | O22: 2 | P22: Resurface + Turn-lane + User-defined #2 | Q22: =Inputs!G27 | R22: =Inputs!J27 | S22: =Inputs!K27 | T22: 0
B23: Set Objective | C23: $Q$32 | N23: 9 | O23: 0 | P23: Do nothing | Q23: =Inputs!G28 | R23: =Inputs!J28 | S23: =Inputs!K28 | T23: 0
B24: To | C24: Max (radio button) | N24: 9 | O24: 1 | P24: Resurface + Turn-lane improvements | Q24: =Inputs!G29 | R24: =Inputs!J29 | S24: =Inputs!K29 | T24: 0
B25: By Changing Cells | C25: $T$6:$T$26 | N25: 10 | O25: 0 | P25: Do nothing | Q25: =Inputs!G30 | R25: =Inputs!J30 | S25: =Inputs!K30 | T25: 0
B26: Solving Method | C26: Simplex LP | N26: 10 | O26: 1 | P26: Resurface + Widen shoulders 4-6ft + Horiz curve + Turn-lane | Q26: =Inputs!G31 | R26: =Inputs!J31 | S26: =Inputs!K31 | T26: 0
B29: Constraints (click 'Add' for each row) | N29: Aggregates
B30: Cell Reference | C30: Op | D30: Constraint | N30: Total cost | Q30: =SUMPRODUCT(Q6:Q26,T6:T26)
B31: $T$6:$T$26 | C31: bin | D31: — | N31: Total benefit | Q31: =SUMPRODUCT(R6:R26,T6:T26)
B32: $Q$30 | C32: <= | D32: 50000000 | N32: Net benefit (objective) | Q32: =SUMPRODUCT(S6:S26,T6:T26)
B33: $O$37 | C33: <= | D33: 1
B34: $O$38 | C34: <= | D34: 1
B35: $O$39 | C35: <= | D35: 1 | N35: Pick at most one alternative per site
B36: $O$40 | C36: <= | D36: 1 | N36: Site | O36: Sum of decisions | P36: Limit
B37: $O$41 | C37: <= | D37: 1 | N37: 1 | O37: =SUM(T6,T7) | P37: 1
B38: $O$42 | C38: <= | D38: 1 | N38: 2 | O38: =SUM(T8,T9) | P38: 1
B39: $O$43 | C39: <= | D39: 1 | N39: 3 | O39: =SUM(T10,T11) | P39: 1
B40: $O$44 | C40: <= | D40: 1 | N40: 4 | O40: =SUM(T12,T13) | P40: 1
B41: $O$45 | C41: <= | D41: 1 | N41: 5 | O41: =SUM(T14,T15) | P41: 1
B42: $O$46 | C42: <= | D42: 1 | N42: 6 | O42: =SUM(T16,T17) | P42: 1
N43: 7 | O43: =SUM(T18,T19) | P43: 1
B44: Bottom of dialog | N44: 8 | O44: =SUM(T20,T21,T22) | P44: 1
B45: Make Unconstrained Vars Non-Negative | C45: checked (default) | N45: 9 | O45: =SUM(T23,T24) | P45: 1
...

Sheet Results
B2: Results
B4: Summary
B5: Match indicator | C5: =IF(SUM(Optimization!T6:T26)=0,"Run Solver",IF(ROUND(Optimization!Q32,0)=ROUND(D5,0),"PASS","FAIL")) | D5: 6159512
B7: Quantity | C7: Solver result | D7: Expected
B8: Total cost | C8: =Optimization!Q30 | D8: 16271247
B9: Total net benefit | C9: =Optimization!Q32 | D9: 6159512
B11: Selected alternatives
B12: Site | C12: Alt | D12: Description
B13: 1 | C13: =Optimization!T6*Optimization!O6+Optimization!T7*Optimization!O7 | D13: =IF(Optimization!T6=1,Optimization!P6,IF(Optimization!T7=1,Optimization!P7,"(none selected)"))
B14: 2 | C14: =Optimization!T8*Optimization!O8+Optimization!T9*Optimization!O9 | D14: =IF(Optimization!T8=1,Optimization!P8,IF(Optimization!T9=1,Optimization!P9,"(none selected)"))
B15: 3 | C15: =Optimization!T10*Optimization!O10+Optimization!T11*Optimization!O11 | D15: =IF(Optimization!T10=1,Optimization!P10,IF(Optimization!T11=1,Optimization!P11,"(none selected)"))
B16: 4 | C16: =Optimization!T12*Optimization!O12+Optimization!T13*Optimization!O13 | D16: =IF(Optimization!T12=1,Optimization!P12,IF(Optimization!T13=1,Optimization!P13,"(none selected)"))
B17: 5 | C17: =Optimization!T14*Optimization!O14+Optimization!T15*Optimization!O15 | D17: =IF(Optimization!T14=1,Optimization!P14,IF(Optimization!T15=1,Optimization!P15,"(none selected)"))
B18: 6 | C18: =Optimization!T16*Optimization!O16+Optimization!T17*Optimization!O17 | D18: =IF(Optimization!T16=1,Optimization!P16,IF(Optimization!T17=1,Optimization!P17,"(none selected)"))
B19: 7 | C19: =Optimization!T18*Optimization!O18+Optimization!T19*Optimization!O19 | D19: =IF(Optimization!T18=1,Optimization!P18,IF(Optimization!T19=1,Optimization!P19,"(none selected)"))
B20: 8 | C20: =Optimization!T20*Optimization!O20+Optimization!T21*Optimization!O21+Optimization!T22*Optimization!O22 | D20: =IF(Optimization!T20=1,Optimization!P20,IF(Optimization!T21=1,Optimization!P21,IF(Optimization!T22=1,Optimization!P22,"(none selected)")))
B21: 9 | C21: =Optimization!T23*Optimization!O23+Optimization!T24*Optimization!O24 | D21: =IF(Optimization!T23=1,Optimization!P23,IF(Optimization!T24=1,Optimization!P24,"(none selected)"))
B22: 10 | C22: =Optimization!T25*Optimization!O25+Optimization!T26*Optimization!O26 | D22: =IF(Optimization!T25=1,Optimization!P25,IF(Optimization!T26=1,Optimization!P26,"(none selected)"))
