Workbook

Sheet README
B2: MCBOMs Banihashemi (2007) Intersection Sub-Problem
B4: Purpose
B5: This workbook implements the MCBOMs MILP — the same Mixed-Integer Linear Program specified in Chapter 2 of the Methodology document and implemented in Python in the project's optimizer module — using the Solver add-in built into Microsoft Excel. It validates the MILP against the Banihashemi (2007) 13-intersection sub-problem. The alternatives include left-turn-lane addition, traffic-control changes, sight-distance correction, and skew-angle adjustment, with cost and benefit values computed parametrically using the IHSDM Crash Prediction Module (Banihashemi Eq. 15). All five forms of the MCBOMs MILP — Python, AMPL, GAMS, LP, and this Excel implementation — produce numerically identical results. Project website: https://ttitamu.github.io/mcboms-optimization.
B11: Problem
B12: 13 intersections with 2-5 alternatives each (43 alternatives total). The optimizer chooses at most one alternative per intersection, subject to a $12,000,000 total budget. Some intersections have all-negative net-benefit alternatives, in which case the optimal choice is to select no alternative for that intersection.
B17: Expected result
B18: Quantity | C18: Value
B19: Total expenditure | C19: 3200000
B20: Total net benefit (objective) | C20: 5177251
B21: Budget | C21: 12000000
B22: Budget utilization | C22: 0.26666667
B23: Number of intersections improved | C23: 7
B26: How to run
B27: 1. Open this workbook in Microsoft Excel (desktop). The Solver add-in must be enabled — see 'How to enable the Solver add-in' below if Solver does not appear on the Data tab.
B28: 2. Go to the 'Optimization' sheet. Verify that the decision-variable cells (yellow-shaded, 'Fund? (0/1)' column) are currently 0.
B29: 3. On the Data tab, click Solver. The Solver Parameters dialog opens.
B30: 4. Configure Solver per the instructions on the right-side panel of the 'Optimization' sheet (objective cell, decision range, constraints).
B31: 5. Click Solve. When the Solver Results dialog appears, choose 'Keep Solver Solution' and click OK.
B32: 6. Verify the answer matches the 'Expected result' table above. The 'Results' sheet shows the selected alternatives and a match indicator that displays 'Run Solver' (yellow) before Solver has been used, 'PASS' (green) once the optimal answer is reached, or 'FAIL' (red) if the answer does not match.
B34: How to enable the Solver add-in (one-time setup)
B35: Skip this section if the Solver button is already visible on the Data tab.
B36: 1. File → Options → Add-ins.
B37: 2. At the bottom, set Manage to 'Excel Add-ins' and click Go.
B38: 3. Check the 'Solver Add-in' box and click OK.
... B44: MCBOMs project website — https://ttitamu.github.io/mcboms-optimization

Sheet Inputs
B2: Inputs (Banihashemi 2007 intersection sub-problem)
B3: Per-intersection alternatives with cost and benefit values computed parametrically using the IHSDM Crash Prediction Module (Banihashemi Eq. 15) and standard FHWA-RD-99-207 AMF values. Some alternatives have negative total benefit because the intersection has natural improvement potential below zero (the do-nothing baseline includes ongoing crash and delay costs).
B9: Budget | E9: 12000000
B10: Intersection | C10: Alt | D10: Description | E10: Resurf cost | F10: Safety cost | G10: Total cost | H10: Crash ben | I10: Delay ben | J10: Total ben | K10: Net benefit
B11: 1 | C11: 0 | D11: Int 1 combo 0 | E11: 0 | F11: 0 | G11: =E11+F11 | H11: 0 | I11: 0 | J11: =H11+I11 | K11: =J11-G11
B12: 1 | C12: 1 | D12: Int 1 combo 1 | E12: 0 | F12: 300000 | G12: =E12+F12 | H12: 1147066.6 | I12: 0 | J12: =H12+I12 | K12: =J12-G12
B13: 1 | C13: 2 | D13: Int 1 combo 2 | E13: 0 | F13: 0 | G13: =E13+F13 | H13: -1910462.2 | I13: 0 | J13: =H13+I13 | K13: =J13-G13
B14: 1 | C14: 3 | D14: Int 1 combo 3 | E14: 0 | F14: 300000 | G14: =E14+F14 | H14: 317734.38 | I14: 0 | J14: =H14+I14 | K14: =J14-G14
B15: 2 | C15: 0 | D15: Int 2 combo 0 | E15: 0 | F15: 0 | G15: =E15+F15 | H15: 0 | I15: 0 | J15: =H15+I15 | K15: =J15-G15
B16: 2 | C16: 1 | D16: Int 2 combo 1 | E16: 0 | F16: 300000 | G16: =E16+F16 | H16: 1118018.4 | I16: 0 | J16: =H16+I16 | K16: =J16-G16
B17: 2 | C17: 2 | D17: Int 2 combo 2 | E17: 0 | F17: 0 | G17: =E17+F17 | H17: -1936869.6 | I17: 0 | J17: =H17+I17 | K17: =J17-G17
B18: 2 | C18: 3 | D18: Int 2 combo 3 | E18: 0 | F18: 300000 | G18: =E18+F18 | H18: 270993.31 | I18: 0 | J18: =H18+I18 | K18: =J18-G18
B19: 3 | C19: 0 | D19: Int 3 combo 0 | E19: 0 | F19: 0 | G19: =E19+F19 | H19: 0 | I19: 0 | J19: =H19+I19 | K19: =J19-G19
B20: 3 | C20: 1 | D20: Int 3 combo 1 | E20: 0 | F20: 0 | G20: =E20+F20 | H20: -21355579 | I20: 0 | J20: =H20+I20 | K20: =J20-G20
B21: 4 | C21: 0 | D21: Int 4 combo 0 | E21: 0 | F21: 0 | G21: =E21+F21 | H21: 0 | I21: 0 | J21: =H21+I21 | K21: =J21-G21
B22: 4 | C22: 1 | D22: Int 4 combo 1 | E22: 0 | F22: 0 | G22: =E22+F22 | H22: -15025871 | I22: 0 | J22: =H22+I22 | K22: =J22-G22
... B53: 13 | C53: 4 | D53: Int 13 combo 4 | E53: 0 | F53: 1200000 | G53: =E53+F53 | H53: 1152514.4 | I53: 0 | J53: =H53+I53 | K53: =J53-G53

Sheet Optimization
B2: Optimization (MILP)
B5: Mathematical Formulation | N5: Intersection | O5: Alt | P5: Description | Q5: Cost | R5: Total benefit | S5: Net benefit | T5: Fund? (0/1)
B6: Decision variables | N6: 1 | O6: 0 | P6: Int 1 combo 0 | Q6: =Inputs!G11 | R6: =Inputs!J11 | S6: =Inputs!K11 | T6: 0
B7: x_ij ∈ {0, 1} for each alternative j at site i (range T6:T48, yellow cells) | N7: 1 | O7: 1 | P7: Int 1 combo 1 | Q7: =Inputs!G12 | R7: =Inputs!J12 | S7: =Inputs!K12 | T7: 0
N8: 1 | O8: 2 | P8: Int 1 combo 2 | Q8: =Inputs!G13 | R8: =Inputs!J13 | S8: =Inputs!K13 | T8: 0
B9: Objective | N9: 1 | O9: 3 | P9: Int 1 combo 3 | Q9: =Inputs!G14 | R9: =Inputs!J14 | S9: =Inputs!K14 | T9: 0
B10: Maximize: Z = Σ_i Σ_j NetBenefit_ij × x_ij | N10: 2 | O10: 0 | P10: Int 2 combo 0 | Q10: =Inputs!G15 | R10: =Inputs!J15 | S10: =Inputs!K15 | T10: 0
B11: (computed at cell Q54) | N11: 2 | O11: 1 | P11: Int 2 combo 1 | Q11: =Inputs!G16 | R11: =Inputs!J16 | S11: =Inputs!K16 | T11: 0
N12: 2 | O12: 2 | P12: Int 2 combo 2 | Q12: =Inputs!G17 | R12: =Inputs!J17 | S12: =Inputs!K17 | T12: 0
B13: Subject to | N13: 2 | O13: 3 | P13: Int 2 combo 3 | Q13: =Inputs!G18 | R13: =Inputs!J18 | S13: =Inputs!K18 | T13: 0
B14: Budget: Σ_i Σ_j Cost_ij × x_ij ≤ Budget | N14: 3 | O14: 0 | P14: Int 3 combo 0 | Q14: =Inputs!G19 | R14: =Inputs!J19 | S14: =Inputs!K19 | T14: 0
B15: (computed at Q52, ≤ $12,000,000) | N15: 3 | O15: 1 | P15: Int 3 combo 1 | Q15: =Inputs!G20 | R15: =Inputs!J20 | S15: =Inputs!K20 | T15: 0
B16: Mutex: Σ_j x_ij ≤ 1 for each site i | N16: 4 | O16: 0 | P16: Int 4 combo 0 | Q16: =Inputs!G21 | R16: =Inputs!J21 | S16: =Inputs!K21 | T16: 0
B17: (constraint cells, O59:O71) | N17: 4 | O17: 1 | P17: Int 4 combo 1 | Q17: =Inputs!G22 | R17: =Inputs!J22 | S17: =Inputs!K22 | T17: 0
B18: Binary: x_ij ∈ {0, 1} | N18: 5 | O18: 0 | P18: Int 5 combo 0 | Q18: =Inputs!G23 | R18: =Inputs!J23 | S18: =Inputs!K23 | T18: 0
N19: 5 | O19: 1 | P19: Int 5 combo 1 | Q19: =Inputs!G24 | R19: =Inputs!J24 | S19: =Inputs!K24 | T19: 0
B20: Solver Setup | N20: 5 | O20: 2 | P20: Int 5 combo 2 | Q20: =Inputs!G25 | R20: =Inputs!J25 | S20: =Inputs!K25 | T20: 0
B21: Top of Solver dialog | N21: 5 | O21: 3 | P21: Int 5 combo 3 | Q21: =Inputs!G26 | R21: =Inputs!J26 | S21: =Inputs!K26 | T21: 0
B22: Field | C22: Value | N22: 6 | O22: 0 | P22: Int 6 combo 0 | Q22: =Inputs!G27 | R22: =Inputs!J27 | S22: =Inputs!K27 | T22: 0
B23: Set Objective | C23: $Q$54 | N23: 6 | O23: 1 | P23: Int 6 combo 1 | Q23: =Inputs!G28 | R23: =Inputs!J28 | S23: =Inputs!K28 | T23: 0
B24: To | C24: Max (radio button) | N24: 6 | O24: 2 | P24: Int 6 combo 2 | Q24: =Inputs!G29 | R24: =Inputs!J29 | S24: =Inputs!K29 | T24: 0
B25: By Changing Cells | C25: $T$6:$T$48 | N25: 6 | O25: 3 | P25: Int 6 combo 3 | Q25: =Inputs!G30 | R25: =Inputs!J30 | S25: =Inputs!K30 | T25: 0
B26: Solving Method | C26: Simplex LP | N26: 7 | O26: 0 | P26: Int 7 combo 0 | Q26: =Inputs!G31 | R26: =Inputs!J31 | S26: =Inputs!K31 | T26: 0
N27: 7 | O27: 1 | P27: Int 7 combo 1 | Q27: =Inputs!G32 | R27: =Inputs!J32 | S27: =Inputs!K32 | T27: 0
N28: 7 | O28: 2 | P28: Int 7 combo 2 | Q28: =Inputs!G33 | R28: =Inputs!J33 | S28: =Inputs!K33 | T28: 0
B29: Constraints (click 'Add' for each row) | N29: 7 | O29: 3 | P29: Int 7 combo 3 | Q29: =Inputs!G34 | R29: =Inputs!J34 | S29: =Inputs!K34 | T29: 0
B30: Cell Reference | C30: Op | D30: Constraint | N30: 8 | O30: 0 | P30: Int 8 combo 0 | Q30: =Inputs!G35 | R30: =Inputs!J35 | S30: =Inputs!K35 | T30: 0
B31: $T$6:$T$48 | C31: bin | D31: — | N31: 8 | O31: 1 | P31: Int 8 combo 1 | Q31: =Inputs!G36 | R31: =Inputs!J36 | S31: =Inputs!K36 | T31: 0
B32: $Q$52 | C32: <= | D32: 12000000 | N32: 9 | O32: 0 | P32: Int 9 combo 0 | Q32: =Inputs!G37 | R32: =Inputs!J37 | S32: =Inputs!K37 | T32: 0
B33: $O$59 | C33: <= | D33: 1 | N33: 9 | O33: 1 | P33: Int 9 combo 1 | Q33: =Inputs!G38 | R33: =Inputs!J38 | S33: =Inputs!K38 | T33: 0
B34: $O$60 | C34: <= | D34: 1 | N34: 9 | O34: 2 | P34: Int 9 combo 2 | Q34: =Inputs!G39 | R34: =Inputs!J39 | S34: =Inputs!K39 | T34: 0
B35: $O$61 | C35: <= | D35: 1 | N35: 9 | O35: 3 | P35: Int 9 combo 3 | Q35: =Inputs!G40 | R35: =Inputs!J40 | S35: =Inputs!K40 | T35: 0
B36: $O$62 | C36: <= | D36: 1 | N36: 10 | O36: 0 | P36: Int 10 combo 0 | Q36: =Inputs!G41 | R36: =Inputs!J41 | S36: =Inputs!K41 | T36: 0
B37: $O$63 | C37: <= | D37: 1 | N37: 10 | O37: 1 | P37: Int 10 combo 1 | Q37: =Inputs!G42 | R37: =Inputs!J42 | S37: =Inputs!K42 | T37: 0
B38: $O$64 | C38: <= | D38: 1 | N38: 11 | O38: 0 | P38: Int 11 combo 0 | Q38: =Inputs!G43 | R38: =Inputs!J43 | S38: =Inputs!K43 | T38: 0
B39: $O$65 | C39: <= | D39: 1 | N39: 11 | O39: 1 | P39: Int 11 combo 1 | Q39: =Inputs!G44 | R39: =Inputs!J44 | S39: =Inputs!K44 | T39: 0
B40: $O$66 | C40: <= | D40: 1 | N40: 12 | O40: 0 | P40: Int 12 combo 0 | Q40: =Inputs!G45 | R40: =Inputs!J45 | S40: =Inputs!K45 | T40: 0
B41: $O$67 | C41: <= | D41: 1 | N41: 12 | O41: 1 | P41: Int 12 combo 1 | Q41: =Inputs!G46 | R41: =Inputs!J46 | S41: =Inputs!K46 | T41: 0
... B45: $O$71 | C45: <= | D45: 1 | N45: 13 | O45: 1 | P45: Int 13 combo 1 | Q45: =Inputs!G50 | R45: =Inputs!J50 | S45: =Inputs!K50 | T45: 0
N46: 13 | O46: 2 | P46: Int 13 combo 2 | Q46: =Inputs!G51 | R46: =Inputs!J51 | S46: =Inputs!K51 | T46: 0
...

Sheet Results
B2: Results
B4: Summary
B5: Match indicator | C5: =IF(SUM(Optimization!T6:T48)=0,"Run Solver",IF(ROUND(Optimization!Q54,0)=ROUND(D5,0),"PASS","FAIL")) | D5: 5177251
B7: Quantity | C7: Solver result | D7: Expected
B8: Total cost | C8: =Optimization!Q52 | D8: 3200000
B9: Total net benefit | C9: =Optimization!Q54 | D9: 5177251
B11: Selected alternatives
B12: Intersection | C12: Alt | D12: Description
B13: 1 | C13: =Optimization!T6*Optimization!O6+Optimization!T7*Optimization!O7+Optimization!T8*Optimization!O8+Optimization!T9*Optimization!O9 | D13: =IF(Optimization!T6=1,Optimization!P6,IF(Optimization!T7=1,Optimization!P7,IF(Optimization!T8=1,Optimization!P8,IF(Optimization!T9=1,Optimization!P9,"(none selected)"))))
B14: 2 | C14: =Optimization!T10*Optimization!O10+Optimization!T11*Optimization!O11+Optimization!T12*Optimization!O12+Optimization!T13*Optimization!O13 | D14: =IF(Optimization!T10=1,Optimization!P10,IF(Optimization!T11=1,Optimization!P11,IF(Optimization!T12=1,Optimization!P12,IF(Optimization!T13=1,Optimization!P13,"(none selected)"))))
B15: 3 | C15: =Optimization!T14*Optimization!O14+Optimization!T15*Optimization!O15 | D15: =IF(Optimization!T14=1,Optimization!P14,IF(Optimization!T15=1,Optimization!P15,"(none selected)"))
B16: 4 | C16: =Optimization!T16*Optimization!O16+Optimization!T17*Optimization!O17 | D16: =IF(Optimization!T16=1,Optimization!P16,IF(Optimization!T17=1,Optimization!P17,"(none selected)"))
B17: 5 | C17: =Optimization!T18*Optimization!O18+Optimization!T19*Optimization!O19+Optimization!T20*Optimization!O20+Optimization!T21*Optimization!O21 | D17: =IF(Optimization!T18=1,Optimization!P18,IF(Optimization!T19=1,Optimization!P19,IF(Optimization!T20=1,Optimization!P20,IF(Optimization!T21=1,Optimization!P21,"(none selected)"))))
B18: 6 | C18: =Optimization!T22*Optimization!O22+Optimization!T23*Optimization!O23+Optimization!T24*Optimization!O24+Optimization!T25*Optimization!O25 | D18: =IF(Optimization!T22=1,Optimization!P22,IF(Optimization!T23=1,Optimization!P23,IF(Optimization!T24=1,Optimization!P24,IF(Optimization!T25=1,Optimization!P25,"(none selected)"))))
B19: 7 | C19: =Optimization!T26*Optimization!O26+Optimization!T27*Optimization!O27+Optimization!T28*Optimization!O28+Optimization!T29*Optimization!O29 | D19: =IF(Optimization!T26=1,Optimization!P26,IF(Optimization!T27=1,Optimization!P27,IF(Optimization!T28=1,Optimization!P28,IF(Optimization!T29=1,Optimization!P29,"(none selected)"))))
B20: 8 | C20: =Optimization!T30*Optimization!O30+Optimization!T31*Optimization!O31 | D20: =IF(Optimization!T30=1,Optimization!P30,IF(Optimization!T31=1,Optimization!P31,"(none selected)"))
B21: 9 | C21: =Optimization!T32*Optimization!O32+Optimization!T33*Optimization!O33+Optimization!T34*Optimization!O34+Optimization!T35*Optimization!O35 | D21: =IF(Optimization!T32=1,Optimization!P32,IF(Optimization!T33=1,Optimization!P33,IF(Optimization!T34=1,Optimization!P34,IF(Optimization!T35=1,Optimization!P35,"(none selected)"))))
B22: 10 | C22: =Optimization!T36*Optimization!O36+Optimization!T37*Optimization!O37 | D22: =IF(Optimization!T36=1,Optimization!P36,IF(Optimization!T37=1,Optimization!P37,"(none selected)"))
B23: 11 | C23: =Optimization!T38*Optimization!O38+Optimization!T39*Optimization!O39 | D23: =IF(Optimization!T38=1,Optimization!P38,IF(Optimization!T39=1,Optimization!P39,"(none selected)"))
B24: 12 | C24: =Optimization!T40*Optimization!O40+Optimization!T41*Optimization!O41+Optimization!T42*Optimization!O42+Optimization!T43*Optimization!O43 | D24: =IF(Optimization!T40=1,Optimization!P40,IF(Optimization!T41=1,Optimization!P41,IF(Optimization!T42=1,Optimization!P42,IF(Optimization!T43=1,Optimization!P43,"(none selected)"))))
B25: 13 | C25: =Optimization!T44*Optimization!O44+Optimization!T45*Optimization!O45+Optimization!T46*Optimization!O46+Optimization!T47*Optimization!O47+Optimization!T48*Optimization!O48 | D25: =IF(Optimization!T44=1,Optimization!P44,IF(Optimization!T45=1,Optimization!P45,IF(Optimization!T46=1,Optimization!P46,IF(Optimization!T47=1,Optimization!P47,IF(Optimization!T48=1,Optimization!P48,"(none selected)")))))
